Workbook

Sheet Info
A1: NVIDIA Network Equipment
A2: Snapshot | B2: 2026-10-23
A3: Schema | B3: v10
A4: Timezone | B4: Europe/Warsaw
A5: Source | B5: data/nvidia-interconnects.json

Sheet All products
A1: Section | B1: Model | C1: Variant | D1: Family | E1: Status | F1: Legacy OPN | G1: NVIDIA OPN | H1: Speed | I1: Form factor | J1: Interfaces | K1: Medium | L1: Reach | M1: Fabric | N1: Description | O1: Link | P1: Search text | Q1: Match #
A2: Transceivers | B2: MMS4B10-XM | C2: RHS/TRO | E2: active | F2: — | G2: 980-9IAJ0-00XM00 | H2: 1600G | I2: OSFP-flattop | J2: 2x 800Gb/s MPO-12/APC | K2: SM | L2: max 500 m | M2: ETH | N2: MMS4B10-XM TRO 1600Gbps OSFP Twin-Port 2xDR4, 2xMPO (APC) 1310nm SMF Transceiver (up to 500m) | O2: https://networking-docs.nvidia.com/mms4b10xmtro1600g | P2: Transceivers MMS4B10-XM RHS/TRO active — 980-9IAJ0-00XM00 1600G OSFP-flattop 2x 800Gb/s MPO-12/APC SM max 500 m ETH MMS4B10-XM TRO 1600Gbps OSFP Twin-Port 2xDR4, 2xMPO (APC) 1310nm SMF Transceiver (up to 500m) | Q2: =IF(AND(Search!$B$2<>"",ISNUMBER(SEARCH(Search!$B$2,P2))),MAX(Q$1:Q1)+1,"")
A3: Transceivers | B3: MMS4B10-XM | C3: IHS/TRO | E3: active | F3: — | G3: 980-9IAJ0-00XM01 | H3: 1600G | I3: OSFP-finned | J3: 2x 800Gb/s MPO-12/APC | K3: SM | L3: max 500 m | M3: ETH | N3: MMS4B10-XM TRO 1600Gbps OSFP Twin-Port 2xDR4, 2xMPO (APC) 1310nm SMF Transceiver (up to 500m) | O3: https://networking-docs.nvidia.com/mms4b10xmtro1600g | P3: Transceivers MMS4B10-XM IHS/TRO active — 980-9IAJ0-00XM01 1600G OSFP-finned 2x 800Gb/s MPO-12/APC SM max 500 m ETH MMS4B10-XM TRO 1600Gbps OSFP Twin-Port 2xDR4, 2xMPO (APC) 1310nm SMF Transceiver (up to 500m) | Q3: =IF(AND(Search!$B$2<>"",ISNUMBER(SEARCH(Search!$B$2,P3))),MAX(Q$1:Q2)+1,"")
A4: Transceivers | B4: MMS4C10 | C4: RHS/FRO Gen2 (XDR) | E4: active | F4: — | G4: 980-9IAU0-00XM00 | H4: 1600G | I4: OSFP-flattop | J4: 2x 800Gb/s MPO-12/APC | K4: SM | L4: max 500 m | M4: IB | N4: NVIDIA MMS4C1X FRO 1600Gbps, 2xDR4, Twin-port OSFP, 2xMPO (APC), 1310nm Single Mode Transceiver (up to 500m) | O4: https://networking-docs.nvidia.com/9iau000xmosfptcvr1600 | P4: Transceivers MMS4C10 RHS/FRO Gen2 (XDR) active — 980-9IAU0-00XM00 1600G OSFP-flattop 2x 800Gb/s MPO-12/APC SM max 500 m IB NVIDIA MMS4C1X FRO 1600Gbps, 2xDR4, Twin-port OSFP, 2xMPO (APC), 1310nm Single Mode Transceiver (up to 500m) | Q4: =IF(AND(Search!$B$2<>"",ISNUMBER(SEARCH(Search!$B$2,P4))),MAX(Q$1:Q3)+1,"")
A5: Transceivers | B5: MMS4C10 | C5: IHS/FRO Gen2 (XDR) | E5: active | F5: — | G5: 980-9IAU0-00XM01 | H5: 1600G | I5: OSFP-finned | J5: 2x 800Gb/s MPO-12/APC | K5: SM | L5: max 500 m | M5: IB | N5: NVIDIA MMS4C1X FRO 1600Gbps, 2xDR4, Twin-port OSFP, 2xMPO (APC), 1310nm Single Mode Transceiver (up to 500m) | O5: https://networking-docs.nvidia.com/9iau000xmosfptcvr1600 | P5: Transceivers MMS4C10 IHS/FRO Gen2 (XDR) active — 980-9IAU0-00XM01 1600G OSFP-finned 2x 800Gb/s MPO-12/APC SM max 500 m IB NVIDIA MMS4C1X FRO 1600Gbps, 2xDR4, Twin-port OSFP, 2xMPO (APC), 1310nm Single Mode Transceiver (up to 500m) | Q5: =IF(AND(Search!$B$2<>"",ISNUMBER(SEARCH(Search!$B$2,P5))),MAX(Q$1:Q4)+1,"")
A6: Transceivers | B6: MMS4C11 | C6: RHS/FRO Gen2 (Ethernet) | E6: active | F6: — | G6: 980-9IAU1-00XM00 | H6: 1600G | I6: OSFP-flattop | J6: 2x 800Gb/s MPO-12/APC | K6: SM | L6: max 500 m | M6: ETH | N6: NVIDIA MMS4C1X FRO 1600Gbps, 2xDR4, Twin-port OSFP, 2xMPO (APC), 1310nm Single Mode Transceiver (up to 500m) | O6: https://networking-docs.nvidia.com/9iau000xmosfptcvr1600 | P6: Transceivers MMS4C11 RHS/FRO Gen2 (Ethernet) active — 980-9IAU1-00XM00 1600G OSFP-flattop 2x 800Gb/s MPO-12/APC SM max 500 m ETH NVIDIA MMS4C1X FRO 1600Gbps, 2xDR4, Twin-port OSFP, 2xMPO (APC), 1310nm Single Mode Transceiver (up to 500m) | Q6: =IF(AND(Search!$B$2<>"",ISNUMBER(SEARCH(Search!$B$2,P6))),MAX(Q$1:Q5)+1,"")
A7: Transceivers | B7: MMS4C11 | C7: IHS/FRO Gen2 (Ethernet) | E7: active | F7: — | G7: 980-9IAU1-00XM01 | H7: 1600G | I7: OSFP-finned | J7: 2x 800Gb/s MPO-12/APC | K7: SM | L7: max 500 m | M7: ETH | N7: NVIDIA MMS4C1X FRO 1600Gbps, 2xDR4, Twin-port OSFP, 2xMPO (APC), 1310nm Single Mode Transceiver (up to 500m) | O7: https://networking-docs.nvidia.com/9iau000xmosfptcvr1600 | P7: Transceivers MMS4C11 IHS/FRO Gen2 (Ethernet) active — 980-9IAU1-00XM01 1600G OSFP-finned 2x 800Gb/s MPO-12/APC SM max 500 m ETH NVIDIA MMS4C1X FRO 1600Gbps, 2xDR4, Twin-port OSFP, 2xMPO (APC), 1310nm Single Mode Transceiver (up to 500m) | Q7: =IF(AND(Search!$B$2<>"",ISNUMBER(SEARCH(Search!$B$2,P7))),MAX(Q$1:Q6)+1,"")
A8: Transceivers | B8: MMS4A00 | C8: IHS | E8: active | F8: MMS4A00 | G8: 980-9IAH1-00XM00 | H8: 1600G | I8: OSFP-finned | J8: 2x 800Gb/s MPO-12/APC | K8: SM | L8: max 500 m | M8: IB | N8: NVIDIA MMS4A00 1600Gbps, 2xDR4, Twin-port OSFP, 2xMPO, 1310nm Single Mode Transceiver (up to 500m) | O8: https://networking-docs.nvidia.com/9iahx00xmosfptcvr1600 | P8: Transceivers MMS4A00 IHS active MMS4A00 980-9IAH1-00XM00 1600G OSFP-finned 2x 800Gb/s MPO-12/APC SM max 500 m IB NVIDIA MMS4A00 1600Gbps, 2xDR4, Twin-port OSFP, 2xMPO, 1310nm Single Mode Transceiver (up to 500m) | Q8: =IF(AND(Search!$B$2<>"",ISNUMBER(SEARCH(Search!$B$2,P8))),MAX(Q$1:Q7)+1,"")
A9: Transceivers | B9: MMS4A00 | C9: RHS | E9: planned | F9: — | G9: 980-9IAH0-00XM00 | H9: 1600G | I9: OSFP-flattop | J9: 2x 800Gb/s MPO-12/APC | K9: SM | L9: max 500 m | M9: IB | N9: NVIDIA MMS4A00 1600Gbps, 2xDR4, Twin-port OSFP, 2xMPO, 1310nm Single Mode Transceiver (up to 500m) | O9: https://networking-docs.nvidia.com/9iahx00xmosfptcvr1600 | P9: Transceivers MMS4A00 RHS planned — 980-9IAH0-00XM00 1600G OSFP-flattop 2x 800Gb/s MPO-12/APC SM max 500 m IB NVIDIA MMS4A00 1600Gbps, 2xDR4, Twin-port OSFP, 2xMPO, 1310nm Single Mode Transceiver (up to 500m) | Q9: =IF(AND(Search!$B$2<>"",ISNUMBER(SEARCH(Search!$B$2,P9))),MAX(Q$1:Q8)+1,"")
A10: Transceivers | B10: MMS4A50 | C10: RHS | E10: active | F10: — | G10: 980-9IAS1-00XM00 | H10: 1600G | I10: OSFP-flattop | J10: 2x 800Gb/s Dual LC Duplex | K10: SM | L10: max 2000 m | M10: IB/ETH | N10: NVIDIA MMS4A50 1600Gbps, OSFP, 2xLC-LC, 1310nm SMF, 2xFR4 Twin-port Transceiver (up to 2km) | O10: https://networking-docs.nvidia.com/mms4a501600gosfp | P10: Transceivers MMS4A50 RHS active — 980-9IAS1-00XM00 1600G OSFP-flattop 2x 800Gb/s Dual LC Duplex SM max 2000 m IB/ETH NVIDIA MMS4A50 1600Gbps, OSFP, 2xLC-LC, 1310nm SMF, 2xFR4 Twin-port Transceiver (up to 2km) | Q10: =IF(AND(Search!$B$2<>"",ISNUMBER(SEARCH(Search!$B$2,P10))),MAX(Q$1:Q9)+1,"")
A11: Transceivers | B11: MMS4A50 | C11: IHS | E11: active | F11: — | G11: 980-9IAS0-00XM00 | H11: 1600G | I11: OSFP-finned | J11: 2x 800Gb/s Dual LC Duplex | K11: SM | L11: max 2000 m | M11: IB/ETH | N11: NVIDIA MMS4A50 1600Gbps, OSFP, 2xLC-LC, 1310nm SMF, 2xFR4 Twin-port Transceiver (up to 2km) | O11: https://networking-docs.nvidia.com/mms4a501600gosfp | P11: Transceivers MMS4A50 IHS active — 980-9IAS0-00XM00 1600G OSFP-finned 2x 800Gb/s Dual LC Duplex SM max 2000 m IB/ETH NVIDIA MMS4A50 1600Gbps, OSFP, 2xLC-LC, 1310nm SMF, 2xFR4 Twin-port Transceiver (up to 2km) | Q11: =IF(AND(Search!$B$2<>"",ISNUMBER(SEARCH(Search!$B$2,P11))),MAX(Q$1:Q10)+1,"")
A12: Transceivers | B12: MMA1Z00-NS400 | C12: — | E12: active | F12: MMA1Z00-NS400 | G12: 980-9I693-00NS00 | H12: 400G | I12: QSFP112 | J12: 1x 400Gb/s MPO-12/APC | K12: MM | L12: OM3 30 m, OM4 50 m, max 50 m | M12: IB/ETH | N12: MMA1Z00-NS400 400Gb/s, Single-port, QSFP112 Multimode SR4 Transceivers Product Specifications | O12: https://networking-docs.nvidia.com/mms1z00ns400sr4 | P12: Transceivers MMA1Z00-NS400 — active MMA1Z00-NS400 980-9I693-00NS00 400G QSFP112 1x 400Gb/s MPO-12/APC MM OM3 30 m, OM4 50 m, max 50 m IB/ETH MMA1Z00-NS400 400Gb/s, Single-port, QSFP112 Multimode SR4 Transceivers Product Specifications | Q12: =IF(AND(Search!$B$2<>"",ISNUMBER(SEARCH(Search!$B$2,P12))),MAX(Q$1:Q11)+1,"")
A13: Transceivers | B13: MMS1V00-WM | C13: — | E13: active | F13: MMS1V00-WM | G13: 980-9I16Y-00W000 | H13: 400G | I13: QSFP-DD | J13: 1x 400Gb/s MPO-12/APC | K13: SM | L13: max 500 m | M13: ETH | N13: MMS1V00-WM 400GbE QSFP-DD DR4 Transceiver Product Specifications | O13: https://networking-docs.nvidia.com/mms1v00wm10 | P13: Transceivers MMS1V00-WM — active MMS1V00-WM 980-9I16Y-00W000 400G QSFP-DD 1x 400Gb/s MPO-12/APC SM max 500 m ETH MMS1V00-WM 400GbE QSFP-DD DR4 Transceiver Product Specifications | Q13: =IF(AND(Search!$B$2<>"",ISNUMBER(SEARCH(Search!$B$2,P13))),MAX(Q$1:Q12)+1,"")
... A49: Copper / DAC / ACC | B49: MCP1600-E0xxEyy | C49: — | E49: active | F49: — | G49: MCP1600-E00AE30, MCP1600-E001E30, MCP1600-E01AE30, MCP1600-E002E30, MCP1600-E02AE26, MCP1600-E003E26, MCP1600-E004E26, MCP1600-E005E26 | H49: 100G | I49: QSFP28 | J49: 1x 100Gb/s QSFP28 to QSFP28 | K49: Copper | L49: max 5 m | M49: IB | N49: MCP1600-E0xxEyy 100Gb/s QSFP28 DAC Cable Product Specifications | O49: https://networking-docs.nvidia.com/mcp1600e0xxxeyyspec | P49: Copper / DAC / ACC MCP1600-E0xxEyy — active — MCP1600-E00AE30, MCP1600-E001E30, MCP1600-E01AE30, MCP1600-E002E30, MCP1600-E02AE26, MCP1600-E003E26, MCP1600-E004E26, MCP1600-E005E26 100G QSFP28 1x 100Gb/s QSFP28 to QSFP28 Copper max 5 m IB MCP1600-E0xxEyy 100Gb/s QSFP28 DAC Cable Product Specifications | Q49: =IF(AND(Search!$B$2<>"",ISNUMBER(SEARCH(Search!$B$2,P49))),MAX(Q$1:Q48)+1,"")
A50: Other active LinkX products | B50: MMS4C1X | D50: Transceiver | E50: active | F50: — | G50: 980-9IAU0-00XM00, 980-9IAU0-00XM01, 980-9IAU1-00XM00, 980-9IAU1-00XM01 | H50: 1600G | N50: NVIDIA MMS4C1X FRO 1600Gbps, 2xDR4, Twin-port OSFP, 2xMPO (APC), 1310nm Single Mode Transceiver (up to 500m) | O50: https://networking-docs.nvidia.com/9iau000xmosfptcvr1600 | P50: Other active LinkX products MMS4C1X Transceiver active — 980-9IAU0-00XM00, 980-9IAU0-00XM01, 980-9IAU1-00XM00, 980-9IAU1-00XM01 1600G NVIDIA MMS4C1X FRO 1600Gbps, 2xDR4, Twin-port OSFP, 2xMPO (APC), 1310nm Single Mode Transceiver (up to 500m) | Q50: =IF(AND(Search!$B$2<>"",ISNUMBER(SEARCH(Search!$B$2,P50))),MAX(Q$1:Q49)+1,"")
A51: Other active LinkX products | B51: MAM1Q00A-QSA | D51: Adapter | E51: active | F51: — | G51: — | H51: Accessories | N51: MAM1Q00A-QSA NVIDIA DynamiX QSA™, QSFP+ to SFP+ Adapter Product Specifications | O51: https://networking-docs.nvidia.com/mam1q00aqsadnmx | P51: Other active LinkX products MAM1Q00A-QSA Adapter active — — Accessories MAM1Q00A-QSA NVIDIA DynamiX QSA™, QSFP+ to SFP+ Adapter Product Specifications | Q51: =IF(AND(Search!$B$2<>"",ISNUMBER(SEARCH(Search!$B$2,P51))),MAX(Q$1:Q50)+1,"")
A52: Other active LinkX products | B52: MAM1Q00A-QSA28 | D52: Adapter | E52: active | F52: — | G52: — | H52: Accessories | N52: MAM1Q00A-QSA28 NVIDIA DynamiX QSA™ QSA28, QSFP28 to SFP28 Adapter Product Specifications | O52: https://networking-docs.nvidia.com/mam1q00aqsa28dnmx | P52: Other active LinkX products MAM1Q00A-QSA28 Adapter active — — Accessories MAM1Q00A-QSA28 NVIDIA DynamiX QSA™ QSA28, QSFP28 to SFP28 Adapter Product Specifications | Q52: =IF(AND(Search!$B$2<>"",ISNUMBER(SEARCH(Search!$B$2,P52))),MAX(Q$1:Q51)+1,"")
A53: Other active LinkX products | B53: MFP7E10-Nxxx | D53: Fiber | E53: active | F53: — | G53: — | H53: Accessories | N53: MFP7E10-Nxxx Optical Multimode Fiber Cable Product Specifications | O53: https://networking-docs.nvidia.com/mfp7e10nxxx | P53: Other active LinkX products MFP7E10-Nxxx Fiber active — — Accessories MFP7E10-Nxxx Optical Multimode Fiber Cable Product Specifications | Q53: =IF(AND(Search!$B$2<>"",ISNUMBER(SEARCH(Search!$B$2,P53))),MAX(Q$1:Q52)+1,"")
A54: Other active LinkX products | B54: MFP7E20-Nxxx | D54: Fiber | E54: active | F54: — | G54: — | H54: Accessories | N54: MFP7E20-Nxxx Optical Multimode Splitter Fiber Cable Product Specifications | O54: https://networking-docs.nvidia.com/mfp7e20nxxx | P54: Other active LinkX products MFP7E20-Nxxx Fiber active — — Accessories MFP7E20-Nxxx Optical Multimode Splitter Fiber Cable Product Specifications | Q54: =IF(AND(Search!$B$2<>"",ISNUMBER(SEARCH(Search!$B$2,P54))),MAX(Q$1:Q53)+1,"")
A55: Other active LinkX products | B55: MFP7E30-Nxxx | D55: Fiber | E55: active | F55: — | G55: — | H55: Accessories | N55: MFP7E30-Nxxx MPO-to-MPO Single-mode Fiber Cable Product Specifications | O55: https://networking-docs.nvidia.com/mfp7e30nxxxpub | P55: Other active LinkX products MFP7E30-Nxxx Fiber active — — Accessories MFP7E30-Nxxx MPO-to-MPO Single-mode Fiber Cable Product Specifications | Q55: =IF(AND(Search!$B$2<>"",ISNUMBER(SEARCH(Search!$B$2,P55))),MAX(Q$1:Q54)+1,"")
A56: Other active LinkX products | B56: MFP7E40-Nxxx | D56: Fiber | E56: active | F56: MFP7E40-N003 / MFP7E40-N005 / MFP7E40-N007 / MFP7E40-N010 / MFP7E40-N015 / MFP7E40-N020 / MFP7E40-N030 / MFP7E40-N050 | G56: 980-9I58K-00N003, 980-9I58L-00N005, 980-9I58M-00N007, 980-9I58N-00N010, 980-9I56O-00N015, 980-9I56P-00N020, 980-9I56Q-00N030, 980-9I56R-000050 | H56: Accessories | N56: MFP7E40-Nxxx Single mode 1:2 Fiber Splitter Cable Product Specifications | O56: https://networking-docs.nvidia.com/mfp7e40nxxxpub | P56: Other active LinkX products MFP7E40-Nxxx Fiber active MFP7E40-N003 / MFP7E40-N005 / MFP7E40-N007 / MFP7E40-N010 / MFP7E40-N015 / MFP7E40-N020 / MFP7E40-N030 / MFP7E40-N050 980-9I58K-00N003, 980-9I58L-00N005, 980-9I58M-00N007, 980-9I58N-00N010, 980-9I56O-00N015, 980-9I56P-00N020, 980-9I56Q-00N030, 980-9I56R-000050 Accessories MFP7E40-Nxxx Single mode 1:2 Fiber Splitter Cable Product Specifications | Q56: =IF(AND(Search!$B$2<>"",ISNUMBER(SEARCH(Search!$B$2,P56))),MAX(Q$1:Q55)+1,"")
A57: Ethernet switching | B57: SN6810-LD | D57: Spectrum-6 SN6000 | E57: documented | F57: — | G57: — | H57: 800GbE | J57: 128x MMC-12 800GbE fixed | N57: Spectrum-6 SN6000 2U 800GbE Ethernet switch: 128x MMC-12 (co-packaged optics) | O57: https://networking-docs.nvidia.com/sn6000hw | P57: Ethernet switching SN6810-LD Spectrum-6 SN6000 documented — — 800GbE 128x MMC-12 800GbE fixed Spectrum-6 SN6000 2U 800GbE Ethernet switch: 128x MMC-12 (co-packaged optics) | Q57: =IF(AND(Search!$B$2<>"",ISNUMBER(SEARCH(Search!$B$2,P57))),MAX(Q$1:Q56)+1,"")
A58: Ethernet switching | B58: SN6800-LD | D58: Spectrum-6 SN6000 | E58: documented | F58: — | G58: — | H58: 200GbE | J58: 512x MMC-12 200GbE fixed | N58: Spectrum-6 SN6000 5U 200GbE Ethernet switch: 512x MMC-12 (co-packaged optics) | O58: https://networking-docs.nvidia.com/sn6000hw | P58: Ethernet switching SN6800-LD Spectrum-6 SN6000 documented — — 200GbE 512x MMC-12 200GbE fixed Spectrum-6 SN6000 5U 200GbE Ethernet switch: 512x MMC-12 (co-packaged optics) | Q58: =IF(AND(Search!$B$2<>"",ISNUMBER(SEARCH(Search!$B$2,P58))),MAX(Q$1:Q57)+1,"")
A59: Ethernet switching | B59: SN6600-LD | D59: Spectrum-6 SN6000 | E59: documented | F59: — | G59: — | H59: 800GbE | J59: 64x OSFP 2x800 Gb/s | N59: Spectrum-6 SN6000 2U 800GbE Ethernet switch: 64x OSFP 2x800 Gb/s | O59: https://networking-docs.nvidia.com/sn6000hw | P59: Ethernet switching SN6600-LD Spectrum-6 SN6000 documented — — 800GbE 64x OSFP 2x800 Gb/s Spectrum-6 SN6000 2U 800GbE Ethernet switch: 64x OSFP 2x800 Gb/s | Q59: =IF(AND(Search!$B$2<>"",ISNUMBER(SEARCH(Search!$B$2,P59))),MAX(Q$1:Q58)+1,"")
A60: Ethernet switching | B60: SN6600 | D60: Spectrum-6 SN6000 | E60: documented | F60: — | G60: — | H60: 800GbE | J60: 64x OSFP 2x800 Gb/s | N60: Spectrum-6 SN6000 3U 800GbE Ethernet switch: 64x OSFP 2x800 Gb/s | O60: https://networking-docs.nvidia.com/sn6000hw | P60: Ethernet switching SN6600 Spectrum-6 SN6000 documented — — 800GbE 64x OSFP 2x800 Gb/s Spectrum-6 SN6000 3U 800GbE Ethernet switch: 64x OSFP 2x800 Gb/s | Q60: =IF(AND(Search!$B$2<>"",ISNUMBER(SEARCH(Search!$B$2,P60))),MAX(Q$1:Q59)+1,"")
A61: Ethernet switching | B61: SN6200-LD | D61: Spectrum-6 SN6000 | E61: documented | F61: — | G61: — | H61: 200GbE | J61: 32x OSFP 2x800GbE front; 256x backplane 200G | N61: Spectrum-6 SN6000 1U 200GbE Ethernet switch: 32x OSFP 2x800GbE front + 256x200G backplane | O61: https://networking-docs.nvidia.com/sn6000hw | P61: Ethernet switching SN6200-LD Spectrum-6 SN6000 documented — — 200GbE 32x OSFP 2x800GbE front; 256x backplane 200G Spectrum-6 SN6000 1U 200GbE Ethernet switch: 32x OSFP 2x800GbE front + 256x200G backplane | Q61: =IF(AND(Search!$B$2<>"",ISNUMBER(SEARCH(Search!$B$2,P61))),MAX(Q$1:Q60)+1,"")
A62: Ethernet switching | B62: SN5610 | D62: Spectrum-4 SN5000 | E62: documented | F62: — | G62: 920-9N42F-00RI-3C1 | H62: 800GbE | J62: 64x OSFP 800GbE; 2x SFP28 25GbE | N62: Spectrum-4 SN5000 2U 800GbE Ethernet switch: 64x OSFP 800GbE + 2x SFP28 25GbE | O62: https://networking-docs.nvidia.com/sn5000hw | P62: Ethernet switching SN5610 Spectrum-4 SN5000 documented — 920-9N42F-00RI-3C1 800GbE 64x OSFP 800GbE; 2x SFP28 25GbE Spectrum-4 SN5000 2U 800GbE Ethernet switch: 64x OSFP 800GbE + 2x SFP28 25GbE | Q62: =IF(AND(Search!$B$2<>"",ISNUMBER(SEARCH(Search!$B$2,P62))),MAX(Q$1:Q61)+1,"")
A63: Ethernet switching | B63: SN5600 | D63: Spectrum-4 SN5000 | E63: end_of_life | F63: — | G63: 920-9N42F-00RI-7C0 | H63: 800GbE | J63: 64x OSFP 800GbE; 1x SFP28 25GbE | N63: Spectrum-4 SN5000 2U 800GbE Ethernet switch: 64x OSFP 800GbE + 1x SFP28 25GbE | O63: https://networking-docs.nvidia.com/sn5000hw | P63: Ethernet switching SN5600 Spectrum-4 SN5000 end_of_life — 920-9N42F-00RI-7C0 800GbE 64x OSFP 800GbE; 1x SFP28 25GbE Spectrum-4 SN5000 2U 800GbE Ethernet switch: 64x OSFP 800GbE + 1x SFP28 25GbE | Q63: =IF(AND(Search!$B$2<>"",ISNUMBER(SEARCH(Search!$B$2,P63))),MAX(Q$1:Q62)+1,"")
A64: Ethernet switching | B64: SN5600D | D64: Spectrum-4 SN5000 | E64: documented | F64: — | G64: 920-9N42F-00RI-KC0 | H64: 800GbE | J64: 64x OSFP 800GbE; 1x SFP28 25GbE | N64: Spectrum-4 SN5000 2U 800GbE Ethernet switch: 64x OSFP 800GbE + 1x SFP28 25GbE | O64: https://networking-docs.nvidia.com/sn5000hw | P64: Ethernet switching SN5600D Spectrum-4 SN5000 documented — 920-9N42F-00RI-KC0 800GbE 64x OSFP 800GbE; 1x SFP28 25GbE Spectrum-4 SN5000 2U 800GbE Ethernet switch: 64x OSFP 800GbE + 1x SFP28 25GbE | Q64: =IF(AND(Search!$B$2<>"",ISNUMBER(SEARCH(Search!$B$2,P64))),MAX(Q$1:Q63)+1,"")
A65: Ethernet switching | B65: SN5400 | D65: Spectrum-4 SN5000 | E65: documented | F65: — | G65: 920-9N42C-00RB-7C0, 920-9N42C-00FB-7C0 | H65: 400GbE | J65: 64x QSFP-DD 400GbE; 2x SFP28 25GbE | N65: Spectrum-4 SN5000 2U 400GbE Ethernet switch: 64x QSFP-DD 400GbE + 2x SFP28 25GbE | O65: https://networking-docs.nvidia.com/sn5000hw | P65: Ethernet switching SN5400 Spectrum-4 SN5000 documented — 920-9N42C-00RB-7C0, 920-9N42C-00FB-7C0 400GbE 64x QSFP-DD 400GbE; 2x SFP28 25GbE Spectrum-4 SN5000 2U 400GbE Ethernet switch: 64x QSFP-DD 400GbE + 2x SFP28 25GbE | Q65: =IF(AND(Search!$B$2<>"",ISNUMBER(SEARCH(Search!$B$2,P65))),MAX(Q$1:Q64)+1,"")
A66: Ethernet switching | B66: SN4600C | D66: Spectrum-3 SN4000 | E66: documented | F66: MSN4600-CS2FC / MSN4600-CS2RC | G66: 920-9N302-00F7-0C2, 920-9N302-00R7-0C0 | H66: 100GbE | J66: 64x QSFP28 100GbE | N66: Spectrum-3 SN4000 2U 100GbE Ethernet switch: 64x QSFP28 100GbE | O66: https://networking-docs.nvidia.com/sn4000hw | P66: Ethernet switching SN4600C Spectrum-3 SN4000 documented MSN4600-CS2FC / MSN4600-CS2RC 920-9N302-00F7-0C2, 920-9N302-00R7-0C0 100GbE 64x QSFP28 100GbE Spectrum-3 SN4000 2U 100GbE Ethernet switch: 64x QSFP28 100GbE | Q66: =IF(AND(Search!$B$2<>"",ISNUMBER(SEARCH(Search!$B$2,P66))),MAX(Q$1:Q65)+1,"")
A67: Ethernet switching | B67: SN4700 | D67: Spectrum-3 SN4000 | E67: documented | F67: MSN4700-WS2FC / MSN4700-WS2RC | G67: 920-9N301-00FB-0C0, 920-9N301-00RB-0C0 | H67: 400GbE | J67: 32x QSFP-DD 400GbE | N67: Spectrum-3 SN4000 1U 400GbE Ethernet switch: 32x QSFP-DD 400GbE | O67: https://networking-docs.nvidia.com/sn4000hw | P67: Ethernet switching SN4700 Spectrum-3 SN4000 documented MSN4700-WS2FC / MSN4700-WS2RC 920-9N301-00FB-0C0, 920-9N301-00RB-0C0 400GbE 32x QSFP-DD 400GbE Spectrum-3 SN4000 1U 400GbE Ethernet switch: 32x QSFP-DD 400GbE | Q67: =IF(AND(Search!$B$2<>"",ISNUMBER(SEARCH(Search!$B$2,P67))),MAX(Q$1:Q66)+1,"")
A68: Ethernet switching | B68: SN3420 | D68: Spectrum-2 SN3000 | E68: documented | F68: MSN3420-CB2FC / MSN3420-CB2RC | G68: 920-9N213-00F7-0C0, 920-9N213-00R7-0C0 | H68: 100GbE | J68: 12x QSFP28 100GbE; 48x SFP28 25GbE | N68: Spectrum-2 SN3000 1U 100GbE Ethernet switch: 12x QSFP28 100GbE + 48x SFP28 25GbE | O68: https://networking-docs.nvidia.com/sn3000hw | P68: Ethernet switching SN3420 Spectrum-2 SN3000 documented MSN3420-CB2FC / MSN3420-CB2RC 920-9N213-00F7-0C0, 920-9N213-00R7-0C0 100GbE 12x QSFP28 100GbE; 48x SFP28 25GbE Spectrum-2 SN3000 1U 100GbE Ethernet switch: 12x QSFP28 100GbE + 48x SFP28 25GbE | Q68: =IF(AND(Search!$B$2<>"",ISNUMBER(SEARCH(Search!$B$2,P68))),MAX(Q$1:Q67)+1,"")
... A90: SuperNIC | B90: BlueField-3 SuperNIC | D90: — | E90: documented | F90: — | G90: 900-9D3B4-00CC-EA0, 900-9D3B4-00CV-EA0, 900-9D3B4-00EN-EA0, 900-9D3B4-00PN-EA0, 900-9D3B4-00SC-EA0, 900-9D3B4-00SV-EA0, 900-9D3D4-00EN-HA0, 900-9D3D4-00NN-HA0 | H90: up to 400 Gb/s | J90: QSFP112 up to 400 Gb/s; QSFP56 up to 400 Gb/s; QSFP28 up to 400 Gb/s | N90: BlueField-3 SuperNIC, up to 400 Gb/s: Spectrum-X Ethernet, secure cloud multi-tenancy, deterministic isolated performance | O90: https://networking-docs.nvidia.com/bf3dpu | P90: SuperNIC BlueField-3 SuperNIC — documented — 900-9D3B4-00CC-EA0, 900-9D3B4-00CV-EA0, 900-9D3B4-00EN-EA0, 900-9D3B4-00PN-EA0, 900-9D3B4-00SC-EA0, 900-9D3B4-00SV-EA0, 900-9D3D4-00EN-HA0, 900-9D3D4-00NN-HA0 up to 400 Gb/s QSFP112 up to 400 Gb/s; QSFP56 up to 400 Gb/s; QSFP28 up to 400 Gb/s BlueField-3 SuperNIC, up to 400 Gb/s: Spectrum-X Ethernet, secure cloud multi-tenancy, deterministic isolated performance | Q90: =IF(AND(Search!$B$2<>"",ISNUMBER(SEARCH(Search!$B$2,P90))),MAX(Q$1:Q89)+1,"")
A91: Network adapters | B91: C9180 | D91: ConnectX-9 | E91: MP | F91: — | G91: 900-9X91E-00EB-ST0, 900-9X91E-00EB-DT0, 900-9X91E-00QB-ST0 | H91: 800GbE / XDR 800Gb/s | I91: single-cage OSFP | J91: 1x OSFP 800GbE / XDR 800Gb/s (C9180) | O91: https://networking-docs.nvidia.com/connectx9hw | P91: Network adapters C9180 ConnectX-9 MP — 900-9X91E-00EB-ST0, 900-9X91E-00EB-DT0, 900-9X91E-00QB-ST0 800GbE / XDR 800Gb/s single-cage OSFP 1x OSFP 800GbE / XDR 800Gb/s (C9180) | Q91: =IF(AND(Search!$B$2<>"",ISNUMBER(SEARCH(Search!$B$2,P91))),MAX(Q$1:Q90)+1,"")
A92: Network adapters | B92: C9240 | D92: ConnectX-9 | E92: MP | F92: — | G92: 900-9X91Q-00CN-ST0, 900-9X91Q-00RN-ST0 | H92: 2x400GbE / 400Gb/s IB | I92: dual QSFP112 | J92: 2x QSFP112 2x400GbE / 400Gb/s IB (C9240) | O92: https://networking-docs.nvidia.com/connectx9hw | P92: Network adapters C9240 ConnectX-9 MP — 900-9X91Q-00CN-ST0, 900-9X91Q-00RN-ST0 2x400GbE / 400Gb/s IB dual QSFP112 2x QSFP112 2x400GbE / 400Gb/s IB (C9240) | Q92: =IF(AND(Search!$B$2<>"",ISNUMBER(SEARCH(Search!$B$2,P92))),MAX(Q$1:Q91)+1,"")
A93: Network adapters | B93: C8180 | D93: ConnectX-8 | E93: MP | F93: — | G93: 900-9X81E-00EX-ST0, 900-9X81E-00EX-DT0 | H93: XDR 800Gb/s / 2x400GbE | I93: single-cage OSFP | J93: 1x OSFP XDR 800Gb/s / 2x400GbE (C8180) | O93: https://networking-docs.nvidia.com/connectx8hw | P93: Network adapters C8180 ConnectX-8 MP — 900-9X81E-00EX-ST0, 900-9X81E-00EX-DT0 XDR 800Gb/s / 2x400GbE single-cage OSFP 1x OSFP XDR 800Gb/s / 2x400GbE (C8180) | Q93: =IF(AND(Search!$B$2<>"",ISNUMBER(SEARCH(Search!$B$2,P93))),MAX(Q$1:Q92)+1,"")
A94: Network adapters | B94: C8240 | D94: ConnectX-8 | E94: active | F94: — | G94: 900-9X81Q-00CN-ST0 | H94: 400GbE / 400Gb/s IB | I94: dual QSFP112 | J94: 2x QSFP112 400GbE / 400Gb/s IB (C8240) | O94: https://networking-docs.nvidia.com/connectx8hw | P94: Network adapters C8240 ConnectX-8 active — 900-9X81Q-00CN-ST0 400GbE / 400Gb/s IB dual QSFP112 2x QSFP112 400GbE / 400Gb/s IB (C8240) | Q94: =IF(AND(Search!$B$2<>"",ISNUMBER(SEARCH(Search!$B$2,P94))),MAX(Q$1:Q93)+1,"")
A95: Network adapters | B95: C8220 | D95: ConnectX-8 | E95: prototype | F95: — | G95: 900-9X81Q-00CV-ST0 | H95: up to 400Gb/s aggregate | I95: dual QSFP112 | J95: 2x QSFP112 up to 400Gb/s aggregate (C8220) | O95: https://networking-docs.nvidia.com/connectx8hw | P95: Network adapters C8220 ConnectX-8 prototype — 900-9X81Q-00CV-ST0 up to 400Gb/s aggregate dual QSFP112 2x QSFP112 up to 400Gb/s aggregate (C8220) | Q95: =IF(AND(Search!$B$2<>"",ISNUMBER(SEARCH(Search!$B$2,P95))),MAX(Q$1:Q94)+1,"")
A96: Network adapters | B96: ConnectX-7 | D96: ConnectX-7 | E96: documented | F96: MCX713104AC-ADAT, MCX713104AS-ADAT, MCX713105AS-WEAT, MCX713106AC-CEAT, MCX713106AC-VEAT, MCX713106AS-CEAT, MCX713106AS-VEAT, MCX713114GC-GEAT, MCX713114TC-GEAT, MCX715105AS-WEAT, MCX75310AAC-NEAT, MCX75310AAS-HEAT, MCX75310AAS-NEAT, MCX755106AC-HEAT, MCX755106AS-HEAT, MCX75510AAS-HEAT, MCX75510AAS-NEAT | G96: 900-9X721-003N-DT0, 900-9X721-003N-DT1, 900-9X766-003N-SQ0, 900-9X766-003N-SR0, 900-9X766-003N-ST0, 900-9X7AH-0039-ST1, 900-9X7AH-0039-STZ, 900-9X7AH-004N-CT0, 900-9X7AH-004N-GT0, 900-9X7AH-0076-ST0, 900-9X7AH-0078-DTZ, 900-9X7AH-0078-ST0, 900-9X7AH-0079-DTZ, 900-9X7AH-0086-SQ0, 900-9X7AH-0088-ST0, 900-9X7AO-0003-ST0, 900-9X7AO-00C3-STZ | H96: up to 400Gb/s IB/Ethernet | I96: OSFP / QSFP112 by SKU | J96: OSFP up to 400Gb/s IB/Ethernet (ConnectX-7); QSFP112 up to 400Gb/s IB/Ethernet (ConnectX-7) | O96: https://networking-docs.nvidia.com/connectx7hw | P96: Network adapters ConnectX-7 ConnectX-7 documented MCX713104AC-ADAT, MCX713104AS-ADAT, MCX713105AS-WEAT, MCX713106AC-CEAT, MCX713106AC-VEAT, MCX713106AS-CEAT, MCX713106AS-VEAT, MCX713114GC-GEAT, MCX713114TC-GEAT, MCX715105AS-WEAT, MCX75310AAC-NEAT, MCX75310AAS-HEAT, MCX75310AAS-NEAT, MCX755106AC-HEAT, MCX755106AS-HEAT, MCX75510AAS-HEAT, MCX75510AAS-NEAT 900-9X721-003N-DT0, 900-9X721-003N-DT1, 900-9X766-003N-SQ0, 900-9X766-003N-SR0, 900-9X766-003N-ST0, 900-9X7AH-0039-ST1, 900-9X7AH-0039-STZ, 900-9X7AH-004N-CT0, 900-9X7AH-004N-GT0, 900-9X7AH-0076-ST0, 900-9X7AH-0078-DTZ, 900-9X7AH-0078-ST0, 900-9X7AH-0079-DTZ, 900-9X7AH-0086-SQ0, 900-9X7AH-0088-ST0, 900-9X7AO-0003-ST0, 900-9X7AO-00C3-STZ up to 400Gb/s IB/Ethernet OSFP / QSFP112 by SKU OSFP up to 400Gb/s IB/Ethernet (ConnectX-7); QSFP112 up to 400Gb/s IB/Ethernet (ConnectX-7) | Q96: =IF(AND(Search!$B$2<>"",ISNUMBER(SEARCH(Search!$B$2,P96))),MAX(Q$1:Q95)+1,"")
...

Sheet Search
A1: Search products
A2: Search text: | C2: Type a model, OPN, speed, connector, fabric (IB/ETH/NVL) or any word; matching is case-insensitive.
A3: Matches: | B3: =MAX('All products'!$Q:$Q) | C3: =IF(B3>200,"Showing first 200 matches only","")
A5: Section | B5: Model | C5: Variant | D5: Family | E5: Status | F5: Legacy OPN | G5: NVIDIA OPN | H5: Speed | I5: Form factor | J5: Interfaces | K5: Medium | L5: Reach | M5: Fabric | N5: Description | O5: Link
A6: =IFERROR(INDEX('All products'!$A$2:$A$109,MATCH(1,'All products'!$Q$2:$Q$109,0))&"","") | B6: =IFERROR(INDEX('All products'!$B$2:$B$109,MATCH(1,'All products'!$Q$2:$Q$109,0))&"","") | C6: =IFERROR(INDEX('All products'!$C$2:$C$109,MATCH(1,'All products'!$Q$2:$Q$109,0))&"","") | D6: =IFERROR(INDEX('All products'!$D$2:$D$109,MATCH(1,'All products'!$Q$2:$Q$109,0))&"","") | E6: =IFERROR(INDEX('All products'!$E$2:$E$109,MATCH(1,'All products'!$Q$2:$Q$109,0))&"","") | F6: =IFERROR(INDEX('All products'!$F$2:$F$109,MATCH(1,'All products'!$Q$2:$Q$109,0))&"","") | G6: =IFERROR(INDEX('All products'!$G$2:$G$109,MATCH(1,'All products'!$Q$2:$Q$109,0))&"","") | H6: =IFERROR(INDEX('All products'!$H$2:$H$109,MATCH(1,'All products'!$Q$2:$Q$109,0))&"","") | I6: =IFERROR(INDEX('All products'!$I$2:$I$109,MATCH(1,'All products'!$Q$2:$Q$109,0))&"","") | J6: =IFERROR(INDEX('All products'!$J$2:$J$109,MATCH(1,'All products'!$Q$2:$Q$109,0))&"","") | K6: =IFERROR(INDEX('All products'!$K$2:$K$109,MATCH(1,'All products'!$Q$2:$Q$109,0))&"","") | L6: =IFERROR(INDEX('All products'!$L$2:$L$109,MATCH(1,'All products'!$Q$2:$Q$109,0))&"","") | M6: =IFERROR(INDEX('All products'!$M$2:$M$109,MATCH(1,'All products'!$Q$2:$Q$109,0))&"","") | N6: =IFERROR(INDEX('All products'!$N$2:$N$109,MATCH(1,'All products'!$Q$2:$Q$109,0))&"","") | O6: =IFERROR(HYPERLINK(INDEX('All products'!$O$2:$O$109,MATCH(1,'All products'!$Q$2:$Q$109,0))),"")
A7: =IFERROR(INDEX('All products'!$A$2:$A$109,MATCH(2,'All products'!$Q$2:$Q$109,0))&"","") | B7: =IFERROR(INDEX('All products'!$B$2:$B$109,MATCH(2,'All products'!$Q$2:$Q$109,0))&"","") | C7: =IFERROR(INDEX('All products'!$C$2:$C$109,MATCH(2,'All products'!$Q$2:$Q$109,0))&"","") | D7: =IFERROR(INDEX('All products'!$D$2:$D$109,MATCH(2,'All products'!$Q$2:$Q$109,0))&"","") | E7: =IFERROR(INDEX('All products'!$E$2:$E$109,MATCH(2,'All products'!$Q$2:$Q$109,0))&"","") | F7: =IFERROR(INDEX('All products'!$F$2:$F$109,MATCH(2,'All products'!$Q$2:$Q$109,0))&"","") | G7: =IFERROR(INDEX('All products'!$G$2:$G$109,MATCH(2,'All products'!$Q$2:$Q$109,0))&"","") | H7: =IFERROR(INDEX('All products'!$H$2:$H$109,MATCH(2,'All products'!$Q$2:$Q$109,0))&"","") | I7: =IFERROR(INDEX('All products'!$I$2:$I$109,MATCH(2,'All products'!$Q$2:$Q$109,0))&"","") | J7: =IFERROR(INDEX('All products'!$J$2:$J$109,MATCH(2,'All products'!$Q$2:$Q$109,0))&"","") | K7: =IFERROR(INDEX('All products'!$K$2:$K$109,MATCH(2,'All products'!$Q$2:$Q$109,0))&"","") | L7: =IFERROR(INDEX('All products'!$L$2:$L$109,MATCH(2,'All products'!$Q$2:$Q$109,0))&"","") | M7: =IFERROR(INDEX('All products'!$M$2:$M$109,MATCH(2,'All products'!$Q$2:$Q$109,0))&"","") | N7: =IFERROR(INDEX('All products'!$N$2:$N$109,MATCH(2,'All products'!$Q$2:$Q$109,0))&"","") | O7: =IFERROR(HYPERLINK(INDEX('All products'!$O$2:$O$109,MATCH(2,'All products'!$Q$2:$Q$109,0))),"")
A8: =IFERROR(INDEX('All products'!$A$2:$A$109,MATCH(3,'All products'!$Q$2:$Q$109,0))&"","") | B8: =IFERROR(INDEX('All products'!$B$2:$B$109,MATCH(3,'All products'!$Q$2:$Q$109,0))&"","") | C8: =IFERROR(INDEX('All products'!$C$2:$C$109,MATCH(3,'All products'!$Q$2:$Q$109,0))&"","") | D8: =IFERROR(INDEX('All products'!$D$2:$D$109,MATCH(3,'All products'!$Q$2:$Q$109,0))&"","") | E8: =IFERROR(INDEX('All products'!$E$2:$E$109,MATCH(3,'All products'!$Q$2:$Q$109,0))&"","") | F8: =IFERROR(INDEX('All products'!$F$2:$F$109,MATCH(3,'All products'!$Q$2:$Q$109,0))&"","") | G8: =IFERROR(INDEX('All products'!$G$2:$G$109,MATCH(3,'All products'!$Q$2:$Q$109,0))&"","") | H8: =IFERROR(INDEX('All products'!$H$2:$H$109,MATCH(3,'All products'!$Q$2:$Q$109,0))&"","") | I8: =IFERROR(INDEX('All products'!$I$2:$I$109,MATCH(3,'All products'!$Q$2:$Q$109,0))&"","") | J8: =IFERROR(INDEX('All products'!$J$2:$J$109,MATCH(3,'All products'!$Q$2:$Q$109,0))&"","") | K8: =IFERROR(INDEX('All products'!$K$2:$K$109,MATCH(3,'All products'!$Q$2:$Q$109,0))&"","") | L8: =IFERROR(INDEX('All products'!$L$2:$L$109,MATCH(3,'All products'!$Q$2:$Q$109,0))&"","") | M8: =IFERROR(INDEX('All products'!$M$2:$M$109,MATCH(3,'All products'!$Q$2:$Q$109,0))&"","") | N8: =IFERROR(INDEX('All products'!$N$2:$N$109,MATCH(3,'All products'!$Q$2:$Q$109,0))&"","") | O8: =IFERROR(HYPERLINK(INDEX('All products'!$O$2:$O$109,MATCH(3,'All products'!$Q$2:$Q$109,0))),"")
A9: =IFERROR(INDEX('All products'!$A$2:$A$109,MATCH(4,'All products'!$Q$2:$Q$109,0))&"","") | B9: =IFERROR(INDEX('All products'!$B$2:$B$109,MATCH(4,'All products'!$Q$2:$Q$109,0))&"","") | C9: =IFERROR(INDEX('All products'!$C$2:$C$109,MATCH(4,'All products'!$Q$2:$Q$109,0))&"","") | D9: =IFERROR(INDEX('All products'!$D$2:$D$109,MATCH(4,'All products'!$Q$2:$Q$109,0))&"","") | E9: =IFERROR(INDEX('All products'!$E$2:$E$109,MATCH(4,'All products'!$Q$2:$Q$109,0))&"","") | F9: =IFERROR(INDEX('All products'!$F$2:$F$109,MATCH(4,'All products'!$Q$2:$Q$109,0))&"","") | G9: =IFERROR(INDEX('All products'!$G$2:$G$109,MATCH(4,'All products'!$Q$2:$Q$109,0))&"","") | H9: =IFERROR(INDEX('All products'!$H$2:$H$109,MATCH(4,'All products'!$Q$2:$Q$109,0))&"","") | I9: =IFERROR(INDEX('All products'!$I$2:$I$109,MATCH(4,'All products'!$Q$2:$Q$109,0))&"","") | J9: =IFERROR(INDEX('All products'!$J$2:$J$109,MATCH(4,'All products'!$Q$2:$Q$109,0))&"","") | K9: =IFERROR(INDEX('All products'!$K$2:$K$109,MATCH(4,'All products'!$Q$2:$Q$109,0))&"","") | L9: =IFERROR(INDEX('All products'!$L$2:$L$109,MATCH(4,'All products'!$Q$2:$Q$109,0))&"","") | M9: =IFERROR(INDEX('All products'!$M$2:$M$109,MATCH(4,'All products'!$Q$2:$Q$109,0))&"","") | N9: =IFERROR(INDEX('All products'!$N$2:$N$109,MATCH(4,'All products'!$Q$2:$Q$109,0))&"","") | O9: =IFERROR(HYPERLINK(INDEX('All products'!$O$2:$O$109,MATCH(4,'All products'!$Q$2:$Q$109,0))),"")
A10: =IFERROR(INDEX('All products'!$A$2:$A$109,MATCH(5,'All products'!$Q$2:$Q$109,0))&"","") | B10: =IFERROR(INDEX('All products'!$B$2:$B$109,MATCH(5,'All products'!$Q$2:$Q$109,0))&"","") | C10: =IFERROR(INDEX('All products'!$C$2:$C$109,MATCH(5,'All products'!$Q$2:$Q$109,0))&"","") | D10: =IFERROR(INDEX('All products'!$D$2:$D$109,MATCH(5,'All products'!$Q$2:$Q$109,0))&"","") | E10: =IFERROR(INDEX('All products'!$E$2:$E$109,MATCH(5,'All products'!$Q$2:$Q$109,0))&"","") | F10: =IFERROR(INDEX('All products'!$F$2:$F$109,MATCH(5,'All products'!$Q$2:$Q$109,0))&"","") | G10: =IFERROR(INDEX('All products'!$G$2:$G$109,MATCH(5,'All products'!$Q$2:$Q$109,0))&"","") | H10: =IFERROR(INDEX('All products'!$H$2:$H$109,MATCH(5,'All products'!$Q$2:$Q$109,0))&"","") | I10: =IFERROR(INDEX('All products'!$I$2:$I$109,MATCH(5,'All products'!$Q$2:$Q$109,0))&"","") | J10: =IFERROR(INDEX('All products'!$J$2:$J$109,MATCH(5,'All products'!$Q$2:$Q$109,0))&"","") | K10: =IFERROR(INDEX('All products'!$K$2:$K$109,MATCH(5,'All products'!$Q$2:$Q$109,0))&"","") | L10: =IFERROR(INDEX('All products'!$L$2:$L$109,MATCH(5,'All products'!$Q$2:$Q$109,0))&"","") | M10: =IFERROR(INDEX('All products'!$M$2:$M$109,MATCH(5,'All products'!$Q$2:$Q$109,0))&"","") | N10: =IFERROR(INDEX('All products'!$N$2:$N$109,MATCH(5,'All products'!$Q$2:$Q$109,0))&"","") | O10: =IFERROR(HYPERLINK(INDEX('All products'!$O$2:$O$109,MATCH(5,'All products'!$Q$2:$Q$109,0))),"")
A11: =IFERROR(INDEX('All products'!$A$2:$A$109,MATCH(6,'All products'!$Q$2:$Q$109,0))&"","") | B11: =IFERROR(INDEX('All products'!$B$2:$B$109,MATCH(6,'All products'!$Q$2:$Q$109,0))&"","") | C11: =IFERROR(INDEX('All products'!$C$2:$C$109,MATCH(6,'All products'!$Q$2:$Q$109,0))&"","") | D11: =IFERROR(INDEX('All products'!$D$2:$D$109,MATCH(6,'All products'!$Q$2:$Q$109,0))&"","") | E11: =IFERROR(INDEX('All products'!$E$2:$E$109,MATCH(6,'All products'!$Q$2:$Q$109,0))&"","") | F11: =IFERROR(INDEX('All products'!$F$2:$F$109,MATCH(6,'All products'!$Q$2:$Q$109,0))&"","") | G11: =IFERROR(INDEX('All products'!$G$2:$G$109,MATCH(6,'All products'!$Q$2:$Q$109,0))&"","") | H11: =IFERROR(INDEX('All products'!$H$2:$H$109,MATCH(6,'All products'!$Q$2:$Q$109,0))&"","") | I11: =IFERROR(INDEX('All products'!$I$2:$I$109,MATCH(6,'All products'!$Q$2:$Q$109,0))&"","") | J11: =IFERROR(INDEX('All products'!$J$2:$J$109,MATCH(6,'All products'!$Q$2:$Q$109,0))&"","") | K11: =IFERROR(INDEX('All products'!$K$2:$K$109,MATCH(6,'All products'!$Q$2:$Q$109,0))&"","") | L11: =IFERROR(INDEX('All products'!$L$2:$L$109,MATCH(6,'All products'!$Q$2:$Q$109,0))&"","") | M11: =IFERROR(INDEX('All products'!$M$2:$M$109,MATCH(6,'All products'!$Q$2:$Q$109,0))&"","") | N11: =IFERROR(INDEX('All products'!$N$2:$N$109,MATCH(6,'All products'!$Q$2:$Q$109,0))&"","") | O11: =IFERROR(HYPERLINK(INDEX('All products'!$O$2:$O$109,MATCH(6,'All products'!$Q$2:$Q$109,0))),"")
A12: =IFERROR(INDEX('All products'!$A$2:$A$109,MATCH(7,'All products'!$Q$2:$Q$109,0))&"","") | B12: =IFERROR(INDEX('All products'!$B$2:$B$109,MATCH(7,'All products'!$Q$2:$Q$109,0))&"","") | C12: =IFERROR(INDEX('All products'!$C$2:$C$109,MATCH(7,'All products'!$Q$2:$Q$109,0))&"","") | D12: =IFERROR(INDEX('All products'!$D$2:$D$109,MATCH(7,'All products'!$Q$2:$Q$109,0))&"","") | E12: =IFERROR(INDEX('All products'!$E$2:$E$109,MATCH(7,'All products'!$Q$2:$Q$109,0))&"","") | F12: =IFERROR(INDEX('All products'!$F$2:$F$109,MATCH(7,'All products'!$Q$2:$Q$109,0))&"","") | G12: =IFERROR(INDEX('All products'!$G$2:$G$109,MATCH(7,'All products'!$Q$2:$Q$109,0))&"","") | H12: =IFERROR(INDEX('All products'!$H$2:$H$109,MATCH(7,'All products'!$Q$2:$Q$109,0))&"","") | I12: =IFERROR(INDEX('All products'!$I$2:$I$109,MATCH(7,'All products'!$Q$2:$Q$109,0))&"","") | J12: =IFERROR(INDEX('All products'!$J$2:$J$109,MATCH(7,'All products'!$Q$2:$Q$109,0))&"","") | K12: =IFERROR(INDEX('All products'!$K$2:$K$109,MATCH(7,'All products'!$Q$2:$Q$109,0))&"","") | L12: =IFERROR(INDEX('All products'!$L$2:$L$109,MATCH(7,'All products'!$Q$2:$Q$109,0))&"","") | M12: =IFERROR(INDEX('All products'!$M$2:$M$109,MATCH(7,'All products'!$Q$2:$Q$109,0))&"","") | N12: =IFERROR(INDEX('All products'!$N$2:$N$109,MATCH(7,'All products'!$Q$2:$Q$109,0))&"","") | O12: =IFERROR(HYPERLINK(INDEX('All products'!$O$2:$O$109,MATCH(7,'All products'!$Q$2:$Q$109,0))),"")
A13: =IFERROR(INDEX('All products'!$A$2:$A$109,MATCH(8,'All products'!$Q$2:$Q$109,0))&"","") | B13: =IFERROR(INDEX('All products'!$B$2:$B$109,MATCH(8,'All products'!$Q$2:$Q$109,0))&"","") | C13: =IFERROR(INDEX('All products'!$C$2:$C$109,MATCH(8,'All products'!$Q$2:$Q$109,0))&"","") | D13: =IFERROR(INDEX('All products'!$D$2:$D$109,MATCH(8,'All products'!$Q$2:$Q$109,0))&"","") | E13: =IFERROR(INDEX('All products'!$E$2:$E$109,MATCH(8,'All products'!$Q$2:$Q$109,0))&"","") | F13: =IFERROR(INDEX('All products'!$F$2:$F$109,MATCH(8,'All products'!$Q$2:$Q$109,0))&"","") | G13: =IFERROR(INDEX('All products'!$G$2:$G$109,MATCH(8,'All products'!$Q$2:$Q$109,0))&"","") | H13: =IFERROR(INDEX('All products'!$H$2:$H$109,MATCH(8,'All products'!$Q$2:$Q$109,0))&"","") | I13: =IFERROR(INDEX('All products'!$I$2:$I$109,MATCH(8,'All products'!$Q$2:$Q$109,0))&"","") | J13: =IFERROR(INDEX('All products'!$J$2:$J$109,MATCH(8,'All products'!$Q$2:$Q$109,0))&"","") | K13: =IFERROR(INDEX('All products'!$K$2:$K$109,MATCH(8,'All products'!$Q$2:$Q$109,0))&"","") | L13: =IFERROR(INDEX('All products'!$L$2:$L$109,MATCH(8,'All products'!$Q$2:$Q$109,0))&"","") | M13: =IFERROR(INDEX('All products'!$M$2:$M$109,MATCH(8,'All products'!$Q$2:$Q$109,0))&"","") | N13: =IFERROR(INDEX('All products'!$N$2:$N$109,MATCH(8,'All products'!$Q$2:$Q$109,0))&"","") | O13: =IFERROR(HYPERLINK(INDEX('All products'!$O$2:$O$109,MATCH(8,'All products'!$Q$2:$Q$109,0))),"")
A14: =IFERROR(INDEX('All products'!$A$2:$A$109,MATCH(9,'All products'!$Q$2:$Q$109,0))&"","") | B14: =IFERROR(INDEX('All products'!$B$2:$B$109,MATCH(9,'All products'!$Q$2:$Q$109,0))&"","") | C14: =IFERROR(INDEX('All products'!$C$2:$C$109,MATCH(9,'All products'!$Q$2:$Q$109,0))&"","") | D14: =IFERROR(INDEX('All products'!$D$2:$D$109,MATCH(9,'All products'!$Q$2:$Q$109,0))&"","") | E14: =IFERROR(INDEX('All products'!$E$2:$E$109,MATCH(9,'All products'!$Q$2:$Q$109,0))&"","") | F14: =IFERROR(INDEX('All products'!$F$2:$F$109,MATCH(9,'All products'!$Q$2:$Q$109,0))&"","") | G14: =IFERROR(INDEX('All products'!$G$2:$G$109,MATCH(9,'All products'!$Q$2:$Q$109,0))&"","") | H14: =IFERROR(INDEX('All products'!$H$2:$H$109,MATCH(9,'All products'!$Q$2:$Q$109,0))&"","") | I14: =IFERROR(INDEX('All products'!$I$2:$I$109,MATCH(9,'All products'!$Q$2:$Q$109,0))&"","") | J14: =IFERROR(INDEX('All products'!$J$2:$J$109,MATCH(9,'All products'!$Q$2:$Q$109,0))&"","") | K14: =IFERROR(INDEX('All products'!$K$2:$K$109,MATCH(9,'All products'!$Q$2:$Q$109,0))&"","") | L14: =IFERROR(INDEX('All products'!$L$2:$L$109,MATCH(9,'All products'!$Q$2:$Q$109,0))&"","") | M14: =IFERROR(INDEX('All products'!$M$2:$M$109,MATCH(9,'All products'!$Q$2:$Q$109,0))&"","") | N14: =IFERROR(INDEX('All products'!$N$2:$N$109,MATCH(9,'All products'!$Q$2:$Q$109,0))&"","") | O14: =IFERROR(HYPERLINK(INDEX('All products'!$O$2:$O$109,MATCH(9,'All products'!$Q$2:$Q$109,0))),"")
A15: =IFERROR(INDEX('All products'!$A$2:$A$109,MATCH(10,'All products'!$Q$2:$Q$109,0))&"","") | B15: =IFERROR(INDEX('All products'!$B$2:$B$109,MATCH(10,'All products'!$Q$2:$Q$109,0))&"","") | C15: =IFERROR(INDEX('All products'!$C$2:$C$109,MATCH(10,'All products'!$Q$2:$Q$109,0))&"","") | D15: =IFERROR(INDEX('All products'!$D$2:$D$109,MATCH(10,'All products'!$Q$2:$Q$109,0))&"","") | E15: =IFERROR(INDEX('All products'!$E$2:$E$109,MATCH(10,'All products'!$Q$2:$Q$109,0))&"","") | F15: =IFERROR(INDEX('All products'!$F$2:$F$109,MATCH(10,'All products'!$Q$2:$Q$109,0))&"","") | G15: =IFERROR(INDEX('All products'!$G$2:$G$109,MATCH(10,'All products'!$Q$2:$Q$109,0))&"","") | H15: =IFERROR(INDEX('All products'!$H$2:$H$109,MATCH(10,'All products'!$Q$2:$Q$109,0))&"","") | I15: =IFERROR(INDEX('All products'!$I$2:$I$109,MATCH(10,'All products'!$Q$2:$Q$109,0))&"","") | J15: =IFERROR(INDEX('All products'!$J$2:$J$109,MATCH(10,'All products'!$Q$2:$Q$109,0))&"","") | K15: =IFERROR(INDEX('All products'!$K$2:$K$109,MATCH(10,'All products'!$Q$2:$Q$109,0))&"","") | L15: =IFERROR(INDEX('All products'!$L$2:$L$109,MATCH(10,'All products'!$Q$2:$Q$109,0))&"","") | M15: =IFERROR(INDEX('All products'!$M$2:$M$109,MATCH(10,'All products'!$Q$2:$Q$109,0))&"","") | N15: =IFERROR(INDEX('All products'!$N$2:$N$109,MATCH(10,'All products'!$Q$2:$Q$109,0))&"","") | O15: =IFERROR(HYPERLINK(INDEX('All products'!$O$2:$O$109,MATCH(10,'All products'!$Q$2:$Q$109,0))),"")
A16: =IFERROR(INDEX('All products'!$A$2:$A$109,MATCH(11,'All products'!$Q$2:$Q$109,0))&"","") | B16: =IFERROR(INDEX('All products'!$B$2:$B$109,MATCH(11,'All products'!$Q$2:$Q$109,0))&"","") | C16: =IFERROR(INDEX('All products'!$C$2:$C$109,MATCH(11,'All products'!$Q$2:$Q$109,0))&"","") | D16: =IFERROR(INDEX('All products'!$D$2:$D$109,MATCH(11,'All products'!$Q$2:$Q$109,0))&"","") | E16: =IFERROR(INDEX('All products'!$E$2:$E$109,MATCH(11,'All products'!$Q$2:$Q$109,0))&"","") | F16: =IFERROR(INDEX('All products'!$F$2:$F$109,MATCH(11,'All products'!$Q$2:$Q$109,0))&"","") | G16: =IFERROR(INDEX('All products'!$G$2:$G$109,MATCH(11,'All products'!$Q$2:$Q$109,0))&"","") | H16: =IFERROR(INDEX('All products'!$H$2:$H$109,MATCH(11,'All products'!$Q$2:$Q$109,0))&"","") | I16: =IFERROR(INDEX('All products'!$I$2:$I$109,MATCH(11,'All products'!$Q$2:$Q$109,0))&"","") | J16: =IFERROR(INDEX('All products'!$J$2:$J$109,MATCH(11,'All products'!$Q$2:$Q$109,0))&"","") | K16: =IFERROR(INDEX('All products'!$K$2:$K$109,MATCH(11,'All products'!$Q$2:$Q$109,0))&"","") | L16: =IFERROR(INDEX('All products'!$L$2:$L$109,MATCH(11,'All products'!$Q$2:$Q$109,0))&"","") | M16: =IFERROR(INDEX('All products'!$M$2:$M$109,MATCH(11,'All products'!$Q$2:$Q$109,0))&"","") | N16: =IFERROR(INDEX('All products'!$N$2:$N$109,MATCH(11,'All products'!$Q$2:$Q$109,0))&"","") | O16: =IFERROR(HYPERLINK(INDEX('All products'!$O$2:$O$109,MATCH(11,'All products'!$Q$2:$Q$109,0))),"")
A17: =IFERROR(INDEX('All products'!$A$2:$A$109,MATCH(12,'All products'!$Q$2:$Q$109,0))&"","") | B17: =IFERROR(INDEX('All products'!$B$2:$B$109,MATCH(12,'All products'!$Q$2:$Q$109,0))&"","") | C17: =IFERROR(INDEX('All products'!$C$2:$C$109,MATCH(12,'All products'!$Q$2:$Q$109,0))&"","") | D17: =IFERROR(INDEX('All products'!$D$2:$D$109,MATCH(12,'All products'!$Q$2:$Q$109,0))&"","") | E17: =IFERROR(INDEX('All products'!$E$2:$E$109,MATCH(12,'All products'!$Q$2:$Q$109,0))&"","") | F17: =IFERROR(INDEX('All products'!$F$2:$F$109,MATCH(12,'All products'!$Q$2:$Q$109,0))&"","") | G17: =IFERROR(INDEX('All products'!$G$2:$G$109,MATCH(12,'All products'!$Q$2:$Q$109,0))&"","") | H17: =IFERROR(INDEX('All products'!$H$2:$H$109,MATCH(12,'All products'!$Q$2:$Q$109,0))&"","") | I17: =IFERROR(INDEX('All products'!$I$2:$I$109,MATCH(12,'All products'!$Q$2:$Q$109,0))&"","") | J17: =IFERROR(INDEX('All products'!$J$2:$J$109,MATCH(12,'All products'!$Q$2:$Q$109,0))&"","") | K17: =IFERROR(INDEX('All products'!$K$2:$K$109,MATCH(12,'All products'!$Q$2:$Q$109,0))&"","") | L17: =IFERROR(INDEX('All products'!$L$2:$L$109,MATCH(12,'All products'!$Q$2:$Q$109,0))&"","") | M17: =IFERROR(INDEX('All products'!$M$2:$M$109,MATCH(12,'All products'!$Q$2:$Q$109,0))&"","") | N17: =IFERROR(INDEX('All products'!$N$2:$N$109,MATCH(12,'All products'!$Q$2:$Q$109,0))&"","") | O17: =IFERROR(HYPERLINK(INDEX('All products'!$O$2:$O$109,MATCH(12,'All products'!$Q$2:$Q$109,0))),"")
A18: =IFERROR(INDEX('All products'!$A$2:$A$109,MATCH(13,'All products'!$Q$2:$Q$109,0))&"","") | B18: =IFERROR(INDEX('All products'!$B$2:$B$109,MATCH(13,'All products'!$Q$2:$Q$109,0))&"","") | C18: =IFERROR(INDEX('All products'!$C$2:$C$109,MATCH(13,'All products'!$Q$2:$Q$109,0))&"","") | D18: =IFERROR(INDEX('All products'!$D$2:$D$109,MATCH(13,'All products'!$Q$2:$Q$109,0))&"","") | E18: =IFERROR(INDEX('All products'!$E$2:$E$109,MATCH(13,'All products'!$Q$2:$Q$109,0))&"","") | F18: =IFERROR(INDEX('All products'!$F$2:$F$109,MATCH(13,'All products'!$Q$2:$Q$109,0))&"","") | G18: =IFERROR(INDEX('All products'!$G$2:$G$109,MATCH(13,'All products'!$Q$2:$Q$109,0))&"","") | H18: =IFERROR(INDEX('All products'!$H$2:$H$109,MATCH(13,'All products'!$Q$2:$Q$109,0))&"","") | I18: =IFERROR(INDEX('All products'!$I$2:$I$109,MATCH(13,'All products'!$Q$2:$Q$109,0))&"","") | J18: =IFERROR(INDEX('All products'!$J$2:$J$109,MATCH(13,'All products'!$Q$2:$Q$109,0))&"","") | K18: =IFERROR(INDEX('All products'!$K$2:$K$109,MATCH(13,'All products'!$Q$2:$Q$109,0))&"","") | L18: =IFERROR(INDEX('All products'!$L$2:$L$109,MATCH(13,'All products'!$Q$2:$Q$109,0))&"","") | M18: =IFERROR(INDEX('All products'!$M$2:$M$109,MATCH(13,'All products'!$Q$2:$Q$109,0))&"","") | N18: =IFERROR(INDEX('All products'!$N$2:$N$109,MATCH(13,'All products'!$Q$2:$Q$109,0))&"","") | O18: =IFERROR(HYPERLINK(INDEX('All products'!$O$2:$O$109,MATCH(13,'All products'!$Q$2:$Q$109,0))),"")
A19: =IFERROR(INDEX('All products'!$A$2:$A$109,MATCH(14,'All products'!$Q$2:$Q$109,0))&"","") | B19: =IFERROR(INDEX('All products'!$B$2:$B$109,MATCH(14,'All products'!$Q$2:$Q$109,0))&"","") | C19: =IFERROR(INDEX('All products'!$C$2:$C$109,MATCH(14,'All products'!$Q$2:$Q$109,0))&"","") | D19: =IFERROR(INDEX('All products'!$D$2:$D$109,MATCH(14,'All products'!$Q$2:$Q$109,0))&"","") | E19: =IFERROR(INDEX('All products'!$E$2:$E$109,MATCH(14,'All products'!$Q$2:$Q$109,0))&"","") | F19: =IFERROR(INDEX('All products'!$F$2:$F$109,MATCH(14,'All products'!$Q$2:$Q$109,0))&"","") | G19: =IFERROR(INDEX('All products'!$G$2:$G$109,MATCH(14,'All products'!$Q$2:$Q$109,0))&"","") | H19: =IFERROR(INDEX('All products'!$H$2:$H$109,MATCH(14,'All products'!$Q$2:$Q$109,0))&"","") | I19: =IFERROR(INDEX('All products'!$I$2:$I$109,MATCH(14,'All products'!$Q$2:$Q$109,0))&"","") | J19: =IFERROR(INDEX('All products'!$J$2:$J$109,MATCH(14,'All products'!$Q$2:$Q$109,0))&"","") | K19: =IFERROR(INDEX('All products'!$K$2:$K$109,MATCH(14,'All products'!$Q$2:$Q$109,0))&"","") | L19: =IFERROR(INDEX('All products'!$L$2:$L$109,MATCH(14,'All products'!$Q$2:$Q$109,0))&"","") | M19: =IFERROR(INDEX('All products'!$M$2:$M$109,MATCH(14,'All products'!$Q$2:$Q$109,0))&"","") | N19: =IFERROR(INDEX('All products'!$N$2:$N$109,MATCH(14,'All products'!$Q$2:$Q$109,0))&"","") | O19: =IFERROR(HYPERLINK(INDEX('All products'!$O$2:$O$109,MATCH(14,'All products'!$Q$2:$Q$109,0))),"")
A20: =IFERROR(INDEX('All products'!$A$2:$A$109,MATCH(15,'All products'!$Q$2:$Q$109,0))&"","") | B20: =IFERROR(INDEX('All products'!$B$2:$B$109,MATCH(15,'All products'!$Q$2:$Q$109,0))&"","") | C20: =IFERROR(INDEX('All products'!$C$2:$C$109,MATCH(15,'All products'!$Q$2:$Q$109,0))&"","") | D20: =IFERROR(INDEX('All products'!$D$2:$D$109,MATCH(15,'All products'!$Q$2:$Q$109,0))&"","") | E20: =IFERROR(INDEX('All products'!$E$2:$E$109,MATCH(15,'All products'!$Q$2:$Q$109,0))&"","") | F20: =IFERROR(INDEX('All products'!$F$2:$F$109,MATCH(15,'All products'!$Q$2:$Q$109,0))&"","") | G20: =IFERROR(INDEX('All products'!$G$2:$G$109,MATCH(15,'All products'!$Q$2:$Q$109,0))&"","") | H20: =IFERROR(INDEX('All products'!$H$2:$H$109,MATCH(15,'All products'!$Q$2:$Q$109,0))&"","") | I20: =IFERROR(INDEX('All products'!$I$2:$I$109,MATCH(15,'All products'!$Q$2:$Q$109,0))&"","") | J20: =IFERROR(INDEX('All products'!$J$2:$J$109,MATCH(15,'All products'!$Q$2:$Q$109,0))&"","") | K20: =IFERROR(INDEX('All products'!$K$2:$K$109,MATCH(15,'All products'!$Q$2:$Q$109,0))&"","") | L20: =IFERROR(INDEX('All products'!$L$2:$L$109,MATCH(15,'All products'!$Q$2:$Q$109,0))&"","") | M20: =IFERROR(INDEX('All products'!$M$2:$M$109,MATCH(15,'All products'!$Q$2:$Q$109,0))&"","") | N20: =IFERROR(INDEX('All products'!$N$2:$N$109,MATCH(15,'All products'!$Q$2:$Q$109,0))&"","") | O20: =IFERROR(HYPERLINK(INDEX('All products'!$O$2:$O$109,MATCH(15,'All products'!$Q$2:$Q$109,0))),"")
A21: =IFERROR(INDEX('All products'!$A$2:$A$109,MATCH(16,'All products'!$Q$2:$Q$109,0))&"","") | B21: =IFERROR(INDEX('All products'!$B$2:$B$109,MATCH(16,'All products'!$Q$2:$Q$109,0))&"","") | C21: =IFERROR(INDEX('All products'!$C$2:$C$109,MATCH(16,'All products'!$Q$2:$Q$109,0))&"","") | D21: =IFERROR(INDEX('All products'!$D$2:$D$109,MATCH(16,'All products'!$Q$2:$Q$109,0))&"","") | E21: =IFERROR(INDEX('All products'!$E$2:$E$109,MATCH(16,'All products'!$Q$2:$Q$109,0))&"","") | F21: =IFERROR(INDEX('All products'!$F$2:$F$109,MATCH(16,'All products'!$Q$2:$Q$109,0))&"","") | G21: =IFERROR(INDEX('All products'!$G$2:$G$109,MATCH(16,'All products'!$Q$2:$Q$109,0))&"","") | H21: =IFERROR(INDEX('All products'!$H$2:$H$109,MATCH(16,'All products'!$Q$2:$Q$109,0))&"","") | I21: =IFERROR(INDEX('All products'!$I$2:$I$109,MATCH(16,'All products'!$Q$2:$Q$109,0))&"","") | J21: =IFERROR(INDEX('All products'!$J$2:$J$109,MATCH(16,'All products'!$Q$2:$Q$109,0))&"","") | K21: =IFERROR(INDEX('All products'!$K$2:$K$109,MATCH(16,'All products'!$Q$2:$Q$109,0))&"","") | L21: =IFERROR(INDEX('All products'!$L$2:$L$109,MATCH(16,'All products'!$Q$2:$Q$109,0))&"","") | M21: =IFERROR(INDEX('All products'!$M$2:$M$109,MATCH(16,'All products'!$Q$2:$Q$109,0))&"","") | N21: =IFERROR(INDEX('All products'!$N$2:$N$109,MATCH(16,'All products'!$Q$2:$Q$109,0))&"","") | O21: =IFERROR(HYPERLINK(INDEX('All products'!$O$2:$O$109,MATCH(16,'All products'!$Q$2:$Q$109,0))),"")
A22: =IFERROR(INDEX('All products'!$A$2:$A$109,MATCH(17,'All products'!$Q$2:$Q$109,0))&"","") | B22: =IFERROR(INDEX('All products'!$B$2:$B$109,MATCH(17,'All products'!$Q$2:$Q$109,0))&"","") | C22: =IFERROR(INDEX('All products'!$C$2:$C$109,MATCH(17,'All products'!$Q$2:$Q$109,0))&"","") | D22: =IFERROR(INDEX('All products'!$D$2:$D$109,MATCH(17,'All products'!$Q$2:$Q$109,0))&"","") | E22: =IFERROR(INDEX('All products'!$E$2:$E$109,MATCH(17,'All products'!$Q$2:$Q$109,0))&"","") | F22: =IFERROR(INDEX('All products'!$F$2:$F$109,MATCH(17,'All products'!$Q$2:$Q$109,0))&"","") | G22: =IFERROR(INDEX('All products'!$G$2:$G$109,MATCH(17,'All products'!$Q$2:$Q$109,0))&"","") | H22: =IFERROR(INDEX('All products'!$H$2:$H$109,MATCH(17,'All products'!$Q$2:$Q$109,0))&"","") | I22: =IFERROR(INDEX('All products'!$I$2:$I$109,MATCH(17,'All products'!$Q$2:$Q$109,0))&"","") | J22: =IFERROR(INDEX('All products'!$J$2:$J$109,MATCH(17,'All products'!$Q$2:$Q$109,0))&"","") | K22: =IFERROR(INDEX('All products'!$K$2:$K$109,MATCH(17,'All products'!$Q$2:$Q$109,0))&"","") | L22: =IFERROR(INDEX('All products'!$L$2:$L$109,MATCH(17,'All products'!$Q$2:$Q$109,0))&"","") | M22: =IFERROR(INDEX('All products'!$M$2:$M$109,MATCH(17,'All products'!$Q$2:$Q$109,0))&"","") | N22: =IFERROR(INDEX('All products'!$N$2:$N$109,MATCH(17,'All products'!$Q$2:$Q$109,0))&"","") | O22: =IFERROR(HYPERLINK(INDEX('All products'!$O$2:$O$109,MATCH(17,'All products'!$Q$2:$Q$109,0))),"")
A23: =IFERROR(INDEX('All products'!$A$2:$A$109,MATCH(18,'All products'!$Q$2:$Q$109,0))&"","") | B23: =IFERROR(INDEX('All products'!$B$2:$B$109,MATCH(18,'All products'!$Q$2:$Q$109,0))&"","") | C23: =IFERROR(INDEX('All products'!$C$2:$C$109,MATCH(18,'All products'!$Q$2:$Q$109,0))&"","") | D23: =IFERROR(INDEX('All products'!$D$2:$D$109,MATCH(18,'All products'!$Q$2:$Q$109,0))&"","") | E23: =IFERROR(INDEX('All products'!$E$2:$E$109,MATCH(18,'All products'!$Q$2:$Q$109,0))&"","") | F23: =IFERROR(INDEX('All products'!$F$2:$F$109,MATCH(18,'All products'!$Q$2:$Q$109,0))&"","") | G23: =IFERROR(INDEX('All products'!$G$2:$G$109,MATCH(18,'All products'!$Q$2:$Q$109,0))&"","") | H23: =IFERROR(INDEX('All products'!$H$2:$H$109,MATCH(18,'All products'!$Q$2:$Q$109,0))&"","") | I23: =IFERROR(INDEX('All products'!$I$2:$I$109,MATCH(18,'All products'!$Q$2:$Q$109,0))&"","") | J23: =IFERROR(INDEX('All products'!$J$2:$J$109,MATCH(18,'All products'!$Q$2:$Q$109,0))&"","") | K23: =IFERROR(INDEX('All products'!$K$2:$K$109,MATCH(18,'All products'!$Q$2:$Q$109,0))&"","") | L23: =IFERROR(INDEX('All products'!$L$2:$L$109,MATCH(18,'All products'!$Q$2:$Q$109,0))&"","") | M23: =IFERROR(INDEX('All products'!$M$2:$M$109,MATCH(18,'All products'!$Q$2:$Q$109,0))&"","") | N23: =IFERROR(INDEX('All products'!$N$2:$N$109,MATCH(18,'All products'!$Q$2:$Q$109,0))&"","") | O23: =IFERROR(HYPERLINK(INDEX('All products'!$O$2:$O$109,MATCH(18,'All products'!$Q$2:$Q$109,0))),"")
A24: =IFERROR(INDEX('All products'!$A$2:$A$109,MATCH(19,'All products'!$Q$2:$Q$109,0))&"","") | B24: =IFERROR(INDEX('All products'!$B$2:$B$109,MATCH(19,'All products'!$Q$2:$Q$109,0))&"","") | C24: =IFERROR(INDEX('All products'!$C$2:$C$109,MATCH(19,'All products'!$Q$2:$Q$109,0))&"","") | D24: =IFERROR(INDEX('All products'!$D$2:$D$109,MATCH(19,'All products'!$Q$2:$Q$109,0))&"","") | E24: =IFERROR(INDEX('All products'!$E$2:$E$109,MATCH(19,'All products'!$Q$2:$Q$109,0))&"","") | F24: =IFERROR(INDEX('All products'!$F$2:$F$109,MATCH(19,'All products'!$Q$2:$Q$109,0))&"","") | G24: =IFERROR(INDEX('All products'!$G$2:$G$109,MATCH(19,'All products'!$Q$2:$Q$109,0))&"","") | H24: =IFERROR(INDEX('All products'!$H$2:$H$109,MATCH(19,'All products'!$Q$2:$Q$109,0))&"","") | I24: =IFERROR(INDEX('All products'!$I$2:$I$109,MATCH(19,'All products'!$Q$2:$Q$109,0))&"","") | J24: =IFERROR(INDEX('All products'!$J$2:$J$109,MATCH(19,'All products'!$Q$2:$Q$109,0))&"","") | K24: =IFERROR(INDEX('All products'!$K$2:$K$109,MATCH(19,'All products'!$Q$2:$Q$109,0))&"","") | L24: =IFERROR(INDEX('All products'!$L$2:$L$109,MATCH(19,'All products'!$Q$2:$Q$109,0))&"","") | M24: =IFERROR(INDEX('All products'!$M$2:$M$109,MATCH(19,'All products'!$Q$2:$Q$109,0))&"","") | N24: =IFERROR(INDEX('All products'!$N$2:$N$109,MATCH(19,'All products'!$Q$2:$Q$109,0))&"","") | O24: =IFERROR(HYPERLINK(INDEX('All products'!$O$2:$O$109,MATCH(19,'All products'!$Q$2:$Q$109,0))),"")
A25: =IFERROR(INDEX('All products'!$A$2:$A$109,MATCH(20,'All products'!$Q$2:$Q$109,0))&"","") | B25: =IFERROR(INDEX('All products'!$B$2:$B$109,MATCH(20,'All products'!$Q$2:$Q$109,0))&"","") | C25: =IFERROR(INDEX('All products'!$C$2:$C$109,MATCH(20,'All products'!$Q$2:$Q$109,0))&"","") | D25: =IFERROR(INDEX('All products'!$D$2:$D$109,MATCH(20,'All products'!$Q$2:$Q$109,0))&"","") | E25: =IFERROR(INDEX('All products'!$E$2:$E$109,MATCH(20,'All products'!$Q$2:$Q$109,0))&"","") | F25: =IFERROR(INDEX('All products'!$F$2:$F$109,MATCH(20,'All products'!$Q$2:$Q$109,0))&"","") | G25: =IFERROR(INDEX('All products'!$G$2:$G$109,MATCH(20,'All products'!$Q$2:$Q$109,0))&"","") | H25: =IFERROR(INDEX('All products'!$H$2:$H$109,MATCH(20,'All products'!$Q$2:$Q$109,0))&"","") | I25: =IFERROR(INDEX('All products'!$I$2:$I$109,MATCH(20,'All products'!$Q$2:$Q$109,0))&"","") | J25: =IFERROR(INDEX('All products'!$J$2:$J$109,MATCH(20,'All products'!$Q$2:$Q$109,0))&"","") | K25: =IFERROR(INDEX('All products'!$K$2:$K$109,MATCH(20,'All products'!$Q$2:$Q$109,0))&"","") | L25: =IFERROR(INDEX('All products'!$L$2:$L$109,MATCH(20,'All products'!$Q$2:$Q$109,0))&"","") | M25: =IFERROR(INDEX('All products'!$M$2:$M$109,MATCH(20,'All products'!$Q$2:$Q$109,0))&"","") | N25: =IFERROR(INDEX('All products'!$N$2:$N$109,MATCH(20,'All products'!$Q$2:$Q$109,0))&"","") | O25: =IFERROR(HYPERLINK(INDEX('All products'!$O$2:$O$109,MATCH(20,'All products'!$Q$2:$Q$109,0))),"")
A26: =IFERROR(INDEX('All products'!$A$2:$A$109,MATCH(21,'All products'!$Q$2:$Q$109,0))&"","") | B26: =IFERROR(INDEX('All products'!$B$2:$B$109,MATCH(21,'All products'!$Q$2:$Q$109,0))&"","") | C26: =IFERROR(INDEX('All products'!$C$2:$C$109,MATCH(21,'All products'!$Q$2:$Q$109,0))&"","") | D26: =IFERROR(INDEX('All products'!$D$2:$D$109,MATCH(21,'All products'!$Q$2:$Q$109,0))&"","") | E26: =IFERROR(INDEX('All products'!$E$2:$E$109,MATCH(21,'All products'!$Q$2:$Q$109,0))&"","") | F26: =IFERROR(INDEX('All products'!$F$2:$F$109,MATCH(21,'All products'!$Q$2:$Q$109,0))&"","") | G26: =IFERROR(INDEX('All products'!$G$2:$G$109,MATCH(21,'All products'!$Q$2:$Q$109,0))&"","") | H26: =IFERROR(INDEX('All products'!$H$2:$H$109,MATCH(21,'All products'!$Q$2:$Q$109,0))&"","") | I26: =IFERROR(INDEX('All products'!$I$2:$I$109,MATCH(21,'All products'!$Q$2:$Q$109,0))&"","") | J26: =IFERROR(INDEX('All products'!$J$2:$J$109,MATCH(21,'All products'!$Q$2:$Q$109,0))&"","") | K26: =IFERROR(INDEX('All products'!$K$2:$K$109,MATCH(21,'All products'!$Q$2:$Q$109,0))&"","") | L26: =IFERROR(INDEX('All products'!$L$2:$L$109,MATCH(21,'All products'!$Q$2:$Q$109,0))&"","") | M26: =IFERROR(INDEX('All products'!$M$2:$M$109,MATCH(21,'All products'!$Q$2:$Q$109,0))&"","") | N26: =IFERROR(INDEX('All products'!$N$2:$N$109,MATCH(21,'All products'!$Q$2:$Q$109,0))&"","") | O26: =IFERROR(HYPERLINK(INDEX('All products'!$O$2:$O$109,MATCH(21,'All products'!$Q$2:$Q$109,0))),"")
A27: =IFERROR(INDEX('All products'!$A$2:$A$109,MATCH(22,'All products'!$Q$2:$Q$109,0))&"","") | B27: =IFERROR(INDEX('All products'!$B$2:$B$109,MATCH(22,'All products'!$Q$2:$Q$109,0))&"","") | C27: =IFERROR(INDEX('All products'!$C$2:$C$109,MATCH(22,'All products'!$Q$2:$Q$109,0))&"","") | D27: =IFERROR(INDEX('All products'!$D$2:$D$109,MATCH(22,'All products'!$Q$2:$Q$109,0))&"","") | E27: =IFERROR(INDEX('All products'!$E$2:$E$109,MATCH(22,'All products'!$Q$2:$Q$109,0))&"","") | F27: =IFERROR(INDEX('All products'!$F$2:$F$109,MATCH(22,'All products'!$Q$2:$Q$109,0))&"","") | G27: =IFERROR(INDEX('All products'!$G$2:$G$109,MATCH(22,'All products'!$Q$2:$Q$109,0))&"","") | H27: =IFERROR(INDEX('All products'!$H$2:$H$109,MATCH(22,'All products'!$Q$2:$Q$109,0))&"","") | I27: =IFERROR(INDEX('All products'!$I$2:$I$109,MATCH(22,'All products'!$Q$2:$Q$109,0))&"","") | J27: =IFERROR(INDEX('All products'!$J$2:$J$109,MATCH(22,'All products'!$Q$2:$Q$109,0))&"","") | K27: =IFERROR(INDEX('All products'!$K$2:$K$109,MATCH(22,'All products'!$Q$2:$Q$109,0))&"","") | L27: =IFERROR(INDEX('All products'!$L$2:$L$109,MATCH(22,'All products'!$Q$2:$Q$109,0))&"","") | M27: =IFERROR(INDEX('All products'!$M$2:$M$109,MATCH(22,'All products'!$Q$2:$Q$109,0))&"","") | N27: =IFERROR(INDEX('All products'!$N$2:$N$109,MATCH(22,'All products'!$Q$2:$Q$109,0))&"","") | O27: =IFERROR(HYPERLINK(INDEX('All products'!$O$2:$O$109,MATCH(22,'All products'!$Q$2:$Q$109,0))),"")
A28: =IFERROR(INDEX('All products'!$A$2:$A$109,MATCH(23,'All products'!$Q$2:$Q$109,0))&"","") | B28: =IFERROR(INDEX('All products'!$B$2:$B$109,MATCH(23,'All products'!$Q$2:$Q$109,0))&"","") | C28: =IFERROR(INDEX('All products'!$C$2:$C$109,MATCH(23,'All products'!$Q$2:$Q$109,0))&"","") | D28: =IFERROR(INDEX('All products'!$D$2:$D$109,MATCH(23,'All products'!$Q$2:$Q$109,0))&"","") | E28: =IFERROR(INDEX('All products'!$E$2:$E$109,MATCH(23,'All products'!$Q$2:$Q$109,0))&"","") | F28: =IFERROR(INDEX('All products'!$F$2:$F$109,MATCH(23,'All products'!$Q$2:$Q$109,0))&"","") | G28: =IFERROR(INDEX('All products'!$G$2:$G$109,MATCH(23,'All products'!$Q$2:$Q$109,0))&"","") | H28: =IFERROR(INDEX('All products'!$H$2:$H$109,MATCH(23,'All products'!$Q$2:$Q$109,0))&"","") | I28: =IFERROR(INDEX('All products'!$I$2:$I$109,MATCH(23,'All products'!$Q$2:$Q$109,0))&"","") | J28: =IFERROR(INDEX('All products'!$J$2:$J$109,MATCH(23,'All products'!$Q$2:$Q$109,0))&"","") | K28: =IFERROR(INDEX('All products'!$K$2:$K$109,MATCH(23,'All products'!$Q$2:$Q$109,0))&"","") | L28: =IFERROR(INDEX('All products'!$L$2:$L$109,MATCH(23,'All products'!$Q$2:$Q$109,0))&"","") | M28: =IFERROR(INDEX('All products'!$M$2:$M$109,MATCH(23,'All products'!$Q$2:$Q$109,0))&"","") | N28: =IFERROR(INDEX('All products'!$N$2:$N$109,MATCH(23,'All products'!$Q$2:$Q$109,0))&"","") | O28: =IFERROR(HYPERLINK(INDEX('All products'!$O$2:$O$109,MATCH(23,'All products'!$Q$2:$Q$109,0))),"")
